<?xml version="1.0" encoding="UTF-8"?>
<!-- Generated by org.testng.reporters.JUnitReportReporter -->
<testsuite hostname="dj-book" failures="1" tests="20" name="api.test.DataDrivenTests" time="40.645" errors="1" timestamp="2024-11-08T10:30:32 IST" skipped="0">
  <testcase classname="api.test.DataDrivenTests" name="testPostUser" time="1.330"/>
  <testcase classname="api.test.DataDrivenTests" name="testPostUser" time="1.321"/>
  <testcase classname="api.test.DataDrivenTests" name="testPostUser" time="1.286"/>
  <testcase classname="api.test.DataDrivenTests" name="testPostUser" time="1.311"/>
  <testcase classname="api.test.DataDrivenTests" name="testPostUser" time="0.002">
    <error message="For input string: &quot;&quot;" type="java.lang.NumberFormatException">
      <![CDATA[java.lang.NumberFormatException: For input string: ""
at java.base/java.lang.NumberFormatException.forInputString(NumberFormatException.java:67)
at java.base/java.lang.Integer.parseInt(Integer.java:672)
at java.base/java.lang.Integer.parseInt(Integer.java:778)
at api.test.DataDrivenTests.testPostUser(DataDrivenTests.java:20)
at java.base/jdk.internal.reflect.DirectMethodHandleAccessor.invoke(DirectMethodHandleAccessor.java:103)
at java.base/java.lang.reflect.Method.invoke(Method.java:580)
at org.testng.internal.invokers.MethodInvocationHelper.invokeMethod(MethodInvocationHelper.java:141)
at org.testng.internal.invokers.TestInvoker.invokeMethod(TestInvoker.java:686)
at org.testng.internal.invokers.TestInvoker.invokeTestMethod(TestInvoker.java:230)
at org.testng.internal.invokers.MethodRunner.runInSequence(MethodRunner.java:63)
at org.testng.internal.invokers.TestInvoker$MethodInvocationAgent.invoke(TestInvoker.java:992)
at org.testng.internal.invokers.TestInvoker.invokeTestMethods(TestInvoker.java:203)
at org.testng.internal.invokers.TestMethodWorker.invokeTestMethods(TestMethodWorker.java:154)
at org.testng.internal.invokers.TestMethodWorker.run(TestMethodWorker.java:134)
at java.base/java.util.ArrayList.forEach(ArrayList.java:1596)
at org.testng.TestRunner.privateRun(TestRunner.java:739)
at org.testng.TestRunner.run(TestRunner.java:614)
at org.testng.SuiteRunner.runTest(SuiteRunner.java:421)
at org.testng.SuiteRunner.runSequentially(SuiteRunner.java:413)
at org.testng.SuiteRunner.privateRun(SuiteRunner.java:373)
at org.testng.SuiteRunner.run(SuiteRunner.java:312)
at org.testng.SuiteRunnerWorker.runSuite(SuiteRunnerWorker.java:52)
at org.testng.SuiteRunnerWorker.run(SuiteRunnerWorker.java:95)
at org.testng.TestNG.runSuitesSequentially(TestNG.java:1274)
at org.testng.TestNG.runSuitesLocally(TestNG.java:1208)
at org.testng.TestNG.runSuites(TestNG.java:1112)
at org.testng.TestNG.run(TestNG.java:1079)
at org.apache.maven.surefire.testng.TestNGExecutor.run(TestNGExecutor.java:283)
at org.apache.maven.surefire.testng.TestNGXmlTestSuite.execute(TestNGXmlTestSuite.java:75)
at org.apache.maven.surefire.testng.TestNGProvider.invoke(TestNGProvider.java:120)
at org.apache.maven.surefire.booter.ForkedBooter.invokeProviderInSameClassLoader(ForkedBooter.java:384)
at org.apache.maven.surefire.booter.ForkedBooter.runSuitesInProcess(ForkedBooter.java:345)
at org.apache.maven.surefire.booter.ForkedBooter.execute(ForkedBooter.java:126)
at org.apache.maven.surefire.booter.ForkedBooter.main(ForkedBooter.java:418)
]]>
    </error>
  </testcase> <!-- testPostUser -->
  <testcase classname="api.test.DataDrivenTests" name="testPostUser" time="5.524"/>
  <testcase classname="api.test.DataDrivenTests" name="testPostUser" time="1.256"/>
  <testcase classname="api.test.DataDrivenTests" name="testPostUser" time="1.623"/>
  <testcase classname="api.test.DataDrivenTests" name="testPostUser" time="1.296"/>
  <testcase classname="api.test.DataDrivenTests" name="testPostUser" time="1.345"/>
  <testcase classname="api.test.DataDrivenTests" name="testDeleteUser" time="2.639"/>
  <testcase classname="api.test.DataDrivenTests" name="testDeleteUser" time="2.716"/>
  <testcase classname="api.test.DataDrivenTests" name="testDeleteUser" time="1.143">
    <failure message="User does not exist for deletion: " type="java.lang.AssertionError">
      <![CDATA[java.lang.AssertionError: User does not exist for deletion: 
at org.testng.AssertJUnit.fail(AssertJUnit.java:65)
at api.test.DataDrivenTests.testDeleteUser(DataDrivenTests.java:45)
at java.base/jdk.internal.reflect.DirectMethodHandleAccessor.invoke(DirectMethodHandleAccessor.java:103)
at java.base/java.lang.reflect.Method.invoke(Method.java:580)
at org.testng.internal.invokers.MethodInvocationHelper.invokeMethod(MethodInvocationHelper.java:141)
at org.testng.internal.invokers.TestInvoker.invokeMethod(TestInvoker.java:686)
at org.testng.internal.invokers.TestInvoker.invokeTestMethod(TestInvoker.java:230)
at org.testng.internal.invokers.MethodRunner.runInSequence(MethodRunner.java:63)
at org.testng.internal.invokers.TestInvoker$MethodInvocationAgent.invoke(TestInvoker.java:992)
at org.testng.internal.invokers.TestInvoker.invokeTestMethods(TestInvoker.java:203)
at org.testng.internal.invokers.TestMethodWorker.invokeTestMethods(TestMethodWorker.java:154)
at org.testng.internal.invokers.TestMethodWorker.run(TestMethodWorker.java:134)
at java.base/java.util.ArrayList.forEach(ArrayList.java:1596)
at org.testng.TestRunner.privateRun(TestRunner.java:739)
at org.testng.TestRunner.run(TestRunner.java:614)
at org.testng.SuiteRunner.runTest(SuiteRunner.java:421)
at org.testng.SuiteRunner.runSequentially(SuiteRunner.java:413)
at org.testng.SuiteRunner.privateRun(SuiteRunner.java:373)
at org.testng.SuiteRunner.run(SuiteRunner.java:312)
at org.testng.SuiteRunnerWorker.runSuite(SuiteRunnerWorker.java:52)
at org.testng.SuiteRunnerWorker.run(SuiteRunnerWorker.java:95)
at org.testng.TestNG.runSuitesSequentially(TestNG.java:1274)
at org.testng.TestNG.runSuitesLocally(TestNG.java:1208)
at org.testng.TestNG.runSuites(TestNG.java:1112)
at org.testng.TestNG.run(TestNG.java:1079)
at org.apache.maven.surefire.testng.TestNGExecutor.run(TestNGExecutor.java:283)
at org.apache.maven.surefire.testng.TestNGXmlTestSuite.execute(TestNGXmlTestSuite.java:75)
at org.apache.maven.surefire.testng.TestNGProvider.invoke(TestNGProvider.java:120)
at org.apache.maven.surefire.booter.ForkedBooter.invokeProviderInSameClassLoader(ForkedBooter.java:384)
at org.apache.maven.surefire.booter.ForkedBooter.runSuitesInProcess(ForkedBooter.java:345)
at org.apache.maven.surefire.booter.ForkedBooter.execute(ForkedBooter.java:126)
at org.apache.maven.surefire.booter.ForkedBooter.main(ForkedBooter.java:418)
]]>
    </failure>
  </testcase> <!-- testDeleteUser -->
  <testcase classname="api.test.DataDrivenTests" name="testDeleteUser" time="2.563"/>
  <testcase classname="api.test.DataDrivenTests" name="testDeleteUser" time="2.601"/>
  <testcase classname="api.test.DataDrivenTests" name="testDeleteUser" time="2.396"/>
  <testcase classname="api.test.DataDrivenTests" name="testDeleteUser" time="2.640"/>
  <testcase classname="api.test.DataDrivenTests" name="testDeleteUser" time="2.644"/>
  <testcase classname="api.test.DataDrivenTests" name="testDeleteUser" time="2.302"/>
  <testcase classname="api.test.DataDrivenTests" name="testDeleteUser" time="2.707"/>
</testsuite> <!-- api.test.DataDrivenTests -->
